<mujoco model="robothon_v8_ultimate">
    <option timestep="0.002" gravity="0 0 -9.81">
        <flag contact="enable"/>
    </option>
    
    <visual>
        <global offwidth="1920" offheight="1080"/>
        <headlight ambient="0.4 0.4 0.4" diffuse="0.6 0.6 0.6" specular="0.2 0.2 0.2"/>
    </visual>
    
    <asset>
        <texture name="texplane" type="2d" builtin="checker" rgb1="0.85 0.85 0.85" rgb2="0.7 0.7 0.7" width="512" height="512"/>
        <material name="matplane" texture="texplane" texrepeat="5 5" reflectance="0.1"/>
        <material name="red" rgba="0.85 0.2 0.1 1"/>
        <material name="blue" rgba="0.1 0.3 0.85 1"/>
        <material name="green" rgba="0.1 0.75 0.3 1"/>
        <material name="yellow" rgba="0.9 0.8 0.1 1"/>
        <material name="orange" rgba="0.9 0.5 0.1 1"/>
        <material name="metal" rgba="0.5 0.5 0.55 1" specular="0.6"/>
        <material name="wood" rgba="0.65 0.45 0.25 1"/>
    </asset>
    
    <worldbody>
        <!-- 地面 -->
        <geom name="floor" type="plane" size="2 2 0.1" material="matplane"/>
        
        <!-- 灯光 -->
        <light pos="0 0 3" dir="0 0 -1" diffuse="0.8 0.8 0.8"/>
        <light pos="0.5 0.5 2" dir="-0.5 -0.5 -1" diffuse="0.4 0.4 0.4"/>
        
        <!-- 工作台 -->
        <body name="table" pos="0.3 0 0.35">
            <geom name="table_top" type="box" size="0.15 0.15 0.012" material="wood" friction="1.0"/>
            <geom name="leg1" type="cylinder" size="0.012 0.175" pos="0.13 0.13 -0.187" material="wood"/>
            <geom name="leg2" type="cylinder" size="0.012 0.175" pos="-0.13 0.13 -0.187" material="wood"/>
            <geom name="leg3" type="cylinder" size="0.012 0.175" pos="0.13 -0.13 -0.187" material="wood"/>
            <geom name="leg4" type="cylinder" size="0.012 0.175" pos="-0.13 -0.13 -0.187" material="wood"/>
        </body>
        
        <!-- 红色方块（可推动） -->
        <body name="block" pos="0.3 0 0.38">
            <freejoint name="block_joint"/>
            <geom name="block_geom" type="box" size="0.02 0.02 0.02" material="red" mass="0.05" friction="0.8"/>
        </body>
        
        <!-- 蓝色目标区域 -->
        <body name="target_zone" pos="-0.2 0 0.35">
            <geom name="target_geom" type="cylinder" size="0.05 0.001" material="blue"/>
        </body>
        
        <!-- 橙色障碍物 -->
        <body name="obstacle" pos="0.05 0 0.38">
            <geom name="obstacle_geom" type="cylinder" size="0.025 0.03" material="orange" mass="0.1"/>
        </body>
        
        <!-- 机械臂 -->
        <body name="base" pos="0 0 0.3">
            <geom name="base_geom" type="cylinder" size="0.08 0.03" material="metal"/>
            
            <body name="link1" pos="0 0 0.03">
                <joint name="joint1" type="hinge" axis="0 0 1" range="-180 180" damping="0.5"/>
                <geom name="link1_geom" type="capsule" fromto="0 0 0 0 0 0.18" size="0.035" material="blue" friction="0.5"/>
                
                <body name="link2" pos="0 0 0.18">
                    <joint name="joint2" type="hinge" axis="0 1 0" range="-135 135" damping="0.5"/>
                    <geom name="link2_geom" type="capsule" fromto="0 0 0 0 0 0.22" size="0.03" material="green" friction="0.5"/>
                    
                    <body name="link3" pos="0 0 0.22">
                        <joint name="joint3" type="hinge" axis="0 1 0" range="-150 150" damping="0.5"/>
                        <geom name="link3_geom" type="capsule" fromto="0 0 0 0 0 0.18" size="0.022" material="yellow" friction="0.5"/>
                        
                        <!-- 夹爪 -->
                        <body name="gripper_base" pos="0 0 0.18">
                            <geom name="gripper_base_geom" type="box" size="0.012 0.03 0.012" material="metal"/>
                            
                            <body name="left_finger" pos="0 0.03 0.012">
                                <joint name="finger_left" type="slide" axis="0 -1 0" range="0 0.02" damping="0.3"/>
                                <geom name="left_finger_geom" type="box" size="0.006 0.01 0.02" material="metal" friction="2.0"/>
                            </body>
                            
                            <body name="right_finger" pos="0 -0.03 0.012">
                                <joint name="finger_right" type="slide" axis="0 1 0" range="0 0.02" damping="0.3"/>
                                <geom name="right_finger_geom" type="box" size="0.006 0.01 0.02" material="metal" friction="2.0"/>
                            </body>
                            
                            <!-- 传感器站点 -->
                            <site name="touch_site" pos="0 0 0.03" size="0.006"/>
                            <site name="ee_site" pos="0 0 0" size="0.004"/>
                        </body>
                    </body>
                </body>
            </body>
        </body>
    </worldbody>
    
    <!-- 传感器 -->
    <sensor>
        <!-- 触觉传感器 -->
        <touch name="touch_sensor" site="touch_site"/>
        
        <!-- 末端执行器位置 -->
        <framepos name="ee_pos" objtype="body" objname="gripper_base"/>
        
        <!-- 方块位置 -->
        <framepos name="block_pos" objtype="body" objname="block"/>
        
        <!-- 关节位置传感器 -->
        <jointpos name="joint1_pos" joint="joint1"/>
        <jointpos name="joint2_pos" joint="joint2"/>
        <jointpos name="joint3_pos" joint="joint3"/>
        
        <!-- 关节速度传感器 -->
        <jointvel name="joint1_vel" joint="joint1"/>
        <jointvel name="joint2_vel" joint="joint2"/>
        <jointvel name="joint3_vel" joint="joint3"/>
    </sensor>
    
    <!-- 执行器 -->
    <actuator>
        <!-- 3个关节电机 -->
        <motor name="m1" joint="joint1" ctrlrange="-2 2"/>
        <motor name="m2" joint="joint2" ctrlrange="-2 2"/>
        <motor name="m3" joint="joint3" ctrlrange="-2 2"/>
        
        <!-- 夹爪位置控制 -->
        <position name="fingers" joint="finger_left" ctrlrange="0 0.02" kp="60"/>
        <position name="fingers_r" joint="finger_right" ctrlrange="0 0.02" kp="60"/>
    </actuator>
</mujoco>
